2021-06-03 14:34:52,183 - instabot version: 0.117.0 (bot) - INFO - Instabot version: 0.117.0 Started
2021-06-03 14:34:52,183 - instabot version: 0.117.0 (bot) - DEBUG - Bot imported from /mnt/build2/butti/.local/lib/python3.9/site-packages/instabot/bot/bot.py
2021-06-03 14:34:52,184 - instabot version: 0.117.0 (api_login) - INFO - Not yet logged in starting: PRE-LOGIN FLOW!
2021-06-03 14:34:52,185 - instabot version: 0.117.0 (api) - WARNING - HTTPSConnectionPool(host='i.instagram.com', port=443): Max retries exceeded with url: /api/v1/accounts/get_prefill_candidates/ (Caused by NewConnectionError('<urllib3.connection.HTTPSConnection object at 0x7f2426e69790>: Failed to establish a new connection: [Errno -3] Temporary failure in name resolution'))
2021-06-03 14:34:52,186 - instabot version: 0.117.0 (api) - WARNING - HTTPSConnectionPool(host='i.instagram.com', port=443): Max retries exceeded with url: /api/v1/qe/sync/ (Caused by NewConnectionError('<urllib3.connection.HTTPSConnection object at 0x7f2426e697c0>: Failed to establish a new connection: [Errno -3] Temporary failure in name resolution'))
2021-06-03 14:34:52,187 - instabot version: 0.117.0 (api) - WARNING - HTTPSConnectionPool(host='i.instagram.com', port=443): Max retries exceeded with url: /api/v1/launcher/sync/ (Caused by NewConnectionError('<urllib3.connection.HTTPSConnection object at 0x7f2426e69760>: Failed to establish a new connection: [Errno -3] Temporary failure in name resolution'))
2021-06-03 14:34:52,188 - instabot version: 0.117.0 (api) - WARNING - HTTPSConnectionPool(host='i.instagram.com', port=443): Max retries exceeded with url: /api/v1/accounts/contact_point_prefill/ (Caused by NewConnectionError('<urllib3.connection.HTTPSConnection object at 0x7f2426e69220>: Failed to establish a new connection: [Errno -3] Temporary failure in name resolution'))
